package myexception;

public class ExceptionDemo5 {
    public static void main(String[] args) {
     /*
        自己处理 (捕获异常) 灵魂四问:
            灵魂一问:如果try中没有遇到问题，怎么执行?
            灵魂二问:如果try中可能会遇到多个问题，怎么执行?
            灵魂三问:如果try中遇到的问题没有被捕获，怎么执行?
            灵魂四问:如果try中遇到了问题，那么try下面的其他代码还会执行吗?
     */
        /*灵魂一问:如果try中没有遇到问题，怎么执行?
            会把try里面所有的代码全部执行完毕，不会执行catch里面的代码
            注意：
                只有当出现了异常才会执行catch里面的代码
         */

        int[] arr = {1,23,4,5,6};

        try{
            System.out.println(arr[0]);
        }catch (ArrayIndexOutOfBoundsException e){
            System.out.println("索引越界了");
        }

        System.out.println("看看我执行了吗");

    }
}
